[2025-10-04T21:37:20.436+0000] {taskinstance.py:1956} INFO - Dependencies all met for dep_context=non-requeueable deps ti=<TaskInstance: economic_data_daily_update.update_durable_goods_shipments scheduled__2025-10-03T06:00:00+00:00 [queued]>
[2025-10-04T21:37:20.489+0000] {taskinstance.py:1956} INFO - Dependencies all met for dep_context=requeueable deps ti=<TaskInstance: economic_data_daily_update.update_durable_goods_shipments scheduled__2025-10-03T06:00:00+00:00 [queued]>
[2025-10-04T21:37:20.495+0000] {taskinstance.py:2170} INFO - Starting attempt 1 of 3
[2025-10-04T21:37:21.826+0000] {taskinstance.py:2191} INFO - Executing <Task(PythonOperator): update_durable_goods_shipments> on 2025-10-03 06:00:00+00:00
[2025-10-04T21:37:21.847+0000] {standard_task_runner.py:87} INFO - Running: ['airflow', 'tasks', 'run', 'economic_data_daily_update', 'update_durable_goods_shipments', 'scheduled__2025-10-03T06:00:00+00:00', '--job-id', '12', '--raw', '--subdir', 'DAGS_FOLDER/economic_data_daily_update.py', '--cfg-path', '/tmp/tmpn4l3sl9e']
[2025-10-04T21:37:21.844+0000] {standard_task_runner.py:60} INFO - Started process 230 to run task
[2025-10-04T21:37:21.851+0000] {standard_task_runner.py:88} INFO - Job 12: Subtask update_durable_goods_shipments
[2025-10-04T21:37:59.049+0000] {task_command.py:423} INFO - Running <TaskInstance: economic_data_daily_update.update_durable_goods_shipments scheduled__2025-10-03T06:00:00+00:00 [running]> on host c5589f85b7af
[2025-10-04T21:38:00.051+0000] {taskinstance.py:2480} INFO - Exporting env vars: AIRFLOW_CTX_DAG_OWNER='economic_data_team' AIRFLOW_CTX_DAG_ID='economic_data_daily_update' AIRFLOW_CTX_TASK_ID='update_durable_goods_shipments' AIRFLOW_CTX_EXECUTION_DATE='2025-10-03T06:00:00+00:00' AIRFLOW_CTX_TRY_NUMBER='1' AIRFLOW_CTX_DAG_RUN_ID='scheduled__2025-10-03T06:00:00+00:00'
[2025-10-04T21:38:00.077+0000] {taskinstance.py:2698} ERROR - Task failed with exception
Traceback (most recent call last):
  File "/home/airflow/.local/lib/python3.8/site-packages/airflow/models/taskinstance.py", line 433, in _execute_task
    result = execute_callable(context=context, **execute_callable_kwargs)
  File "/home/airflow/.local/lib/python3.8/site-packages/airflow/operators/python.py", line 199, in execute
    return_value = self.execute_callable()
  File "/home/airflow/.local/lib/python3.8/site-packages/airflow/operators/python.py", line 216, in execute_callable
    return self.python_callable(*self.op_args, **self.op_kwargs)
  File "/opt/airflow/dags/economic_data_daily_update.py", line 100, in update_durable_goods_shipments
    result = hook.get_first(last_date_sql, parameters=(series_id,))
  File "/home/airflow/.local/lib/python3.8/site-packages/airflow/providers/common/sql/hooks/sql.py", line 270, in get_first
    return self.run(sql=sql, parameters=parameters, handler=fetch_one_handler)
  File "/home/airflow/.local/lib/python3.8/site-packages/airflow/providers/common/sql/hooks/sql.py", line 391, in run
    with closing(self.get_conn()) as conn:
  File "/home/airflow/.local/lib/python3.8/site-packages/airflow/providers/postgres/hooks/postgres.py", line 128, in get_conn
    conn = deepcopy(self.connection or self.get_connection(conn_id))
  File "/home/airflow/.local/lib/python3.8/site-packages/airflow/hooks/base.py", line 82, in get_connection
    conn = Connection.get_connection_from_secrets(conn_id)
  File "/home/airflow/.local/lib/python3.8/site-packages/airflow/models/connection.py", line 479, in get_connection_from_secrets
    raise AirflowNotFoundException(f"The conn_id `{conn_id}` isn't defined")
airflow.exceptions.AirflowNotFoundException: The conn_id `timescaledb_conn` isn't defined
[2025-10-04T21:38:00.081+0000] {taskinstance.py:1138} INFO - Marking task as UP_FOR_RETRY. dag_id=economic_data_daily_update, task_id=update_durable_goods_shipments, execution_date=20251003T060000, start_date=20251004T213720, end_date=20251004T213800
[2025-10-04T21:38:00.112+0000] {standard_task_runner.py:107} ERROR - Failed to execute job 12 for task update_durable_goods_shipments (The conn_id `timescaledb_conn` isn't defined; 230)
[2025-10-04T21:38:00.150+0000] {local_task_job_runner.py:234} INFO - Task exited with return code 1
[2025-10-04T21:38:03.723+0000] {taskinstance.py:3280} INFO - 0 downstream tasks scheduled from follow-on schedule check
