[2025-10-04T21:40:56.480+0000] {taskinstance.py:1956} INFO - Dependencies all met for dep_context=non-requeueable deps ti=<TaskInstance: economic_data_daily_update.update_benchmark_yields manual__2025-10-04T21:40:48.922904+00:00 [queued]>
[2025-10-04T21:40:56.485+0000] {taskinstance.py:1956} INFO - Dependencies all met for dep_context=requeueable deps ti=<TaskInstance: economic_data_daily_update.update_benchmark_yields manual__2025-10-04T21:40:48.922904+00:00 [queued]>
[2025-10-04T21:40:56.486+0000] {taskinstance.py:2170} INFO - Starting attempt 1 of 3
[2025-10-04T21:40:56.493+0000] {taskinstance.py:2191} INFO - Executing <Task(PythonOperator): update_benchmark_yields> on 2025-10-04 21:40:48.922904+00:00
[2025-10-04T21:40:56.496+0000] {standard_task_runner.py:60} INFO - Started process 464 to run task
[2025-10-04T21:40:56.498+0000] {standard_task_runner.py:87} INFO - Running: ['airflow', 'tasks', 'run', 'economic_data_daily_update', 'update_benchmark_yields', 'manual__2025-10-04T21:40:48.922904+00:00', '--job-id', '55', '--raw', '--subdir', 'DAGS_FOLDER/economic_data_daily_update.py', '--cfg-path', '/tmp/tmp5f2e248w']
[2025-10-04T21:40:56.499+0000] {standard_task_runner.py:88} INFO - Job 55: Subtask update_benchmark_yields
[2025-10-04T21:40:56.525+0000] {task_command.py:423} INFO - Running <TaskInstance: economic_data_daily_update.update_benchmark_yields manual__2025-10-04T21:40:48.922904+00:00 [running]> on host c5589f85b7af
[2025-10-04T21:40:56.667+0000] {taskinstance.py:2480} INFO - Exporting env vars: AIRFLOW_CTX_DAG_OWNER='economic_data_team' AIRFLOW_CTX_DAG_ID='economic_data_daily_update' AIRFLOW_CTX_TASK_ID='update_benchmark_yields' AIRFLOW_CTX_EXECUTION_DATE='2025-10-04T21:40:48.922904+00:00' AIRFLOW_CTX_TRY_NUMBER='1' AIRFLOW_CTX_DAG_RUN_ID='manual__2025-10-04T21:40:48.922904+00:00'
[2025-10-04T21:40:56.676+0000] {taskinstance.py:2698} ERROR - Task failed with exception
Traceback (most recent call last):
  File "/home/airflow/.local/lib/python3.8/site-packages/airflow/models/taskinstance.py", line 433, in _execute_task
    result = execute_callable(context=context, **execute_callable_kwargs)
  File "/home/airflow/.local/lib/python3.8/site-packages/airflow/operators/python.py", line 199, in execute
    return_value = self.execute_callable()
  File "/home/airflow/.local/lib/python3.8/site-packages/airflow/operators/python.py", line 216, in execute_callable
    return self.python_callable(*self.op_args, **self.op_kwargs)
  File "/opt/airflow/dags/economic_data_daily_update.py", line 279, in update_benchmark_yields
    result = hook.get_first(last_date_sql, parameters=(country, maturity, series_id))
  File "/home/airflow/.local/lib/python3.8/site-packages/airflow/providers/common/sql/hooks/sql.py", line 270, in get_first
    return self.run(sql=sql, parameters=parameters, handler=fetch_one_handler)
  File "/home/airflow/.local/lib/python3.8/site-packages/airflow/providers/common/sql/hooks/sql.py", line 391, in run
    with closing(self.get_conn()) as conn:
  File "/home/airflow/.local/lib/python3.8/site-packages/airflow/providers/postgres/hooks/postgres.py", line 128, in get_conn
    conn = deepcopy(self.connection or self.get_connection(conn_id))
  File "/home/airflow/.local/lib/python3.8/site-packages/airflow/hooks/base.py", line 82, in get_connection
    conn = Connection.get_connection_from_secrets(conn_id)
  File "/home/airflow/.local/lib/python3.8/site-packages/airflow/models/connection.py", line 479, in get_connection_from_secrets
    raise AirflowNotFoundException(f"The conn_id `{conn_id}` isn't defined")
airflow.exceptions.AirflowNotFoundException: The conn_id `timescaledb_conn` isn't defined
[2025-10-04T21:40:56.678+0000] {taskinstance.py:1138} INFO - Marking task as UP_FOR_RETRY. dag_id=economic_data_daily_update, task_id=update_benchmark_yields, execution_date=20251004T214048, start_date=20251004T214056, end_date=20251004T214056
[2025-10-04T21:40:56.683+0000] {standard_task_runner.py:107} ERROR - Failed to execute job 55 for task update_benchmark_yields (The conn_id `timescaledb_conn` isn't defined; 464)
[2025-10-04T21:40:56.721+0000] {local_task_job_runner.py:234} INFO - Task exited with return code 1
[2025-10-04T21:40:56.737+0000] {taskinstance.py:3280} INFO - 0 downstream tasks scheduled from follow-on schedule check
