[2025-10-04T21:37:20.408+0000] {taskinstance.py:1956} INFO - Dependencies all met for dep_context=non-requeueable deps ti=<TaskInstance: economic_data_daily_update.update_eia_summary scheduled__2025-10-03T06:00:00+00:00 [queued]>
[2025-10-04T21:37:20.426+0000] {taskinstance.py:1956} INFO - Dependencies all met for dep_context=requeueable deps ti=<TaskInstance: economic_data_daily_update.update_eia_summary scheduled__2025-10-03T06:00:00+00:00 [queued]>
[2025-10-04T21:37:20.429+0000] {taskinstance.py:2170} INFO - Starting attempt 1 of 3
[2025-10-04T21:37:20.870+0000] {taskinstance.py:2191} INFO - Executing <Task(PythonOperator): update_eia_summary> on 2025-10-03 06:00:00+00:00
[2025-10-04T21:37:21.785+0000] {standard_task_runner.py:87} INFO - Running: ['airflow', 'tasks', 'run', 'economic_data_daily_update', 'update_eia_summary', 'scheduled__2025-10-03T06:00:00+00:00', '--job-id', '14', '--raw', '--subdir', 'DAGS_FOLDER/economic_data_daily_update.py', '--cfg-path', '/tmp/tmpxpr9elh8']
[2025-10-04T21:37:21.807+0000] {standard_task_runner.py:88} INFO - Job 14: Subtask update_eia_summary
[2025-10-04T21:37:21.790+0000] {standard_task_runner.py:60} INFO - Started process 229 to run task
[2025-10-04T21:37:21.986+0000] {task_command.py:423} INFO - Running <TaskInstance: economic_data_daily_update.update_eia_summary scheduled__2025-10-03T06:00:00+00:00 [running]> on host c5589f85b7af
[2025-10-04T21:38:00.073+0000] {taskinstance.py:2480} INFO - Exporting env vars: AIRFLOW_CTX_DAG_OWNER='economic_data_team' AIRFLOW_CTX_DAG_ID='economic_data_daily_update' AIRFLOW_CTX_TASK_ID='update_eia_summary' AIRFLOW_CTX_EXECUTION_DATE='2025-10-03T06:00:00+00:00' AIRFLOW_CTX_TRY_NUMBER='1' AIRFLOW_CTX_DAG_RUN_ID='scheduled__2025-10-03T06:00:00+00:00'
[2025-10-04T21:38:00.076+0000] {logging_mixin.py:188} INFO - Updating EIA Summary...
[2025-10-04T21:38:00.094+0000] {taskinstance.py:2698} ERROR - Task failed with exception
Traceback (most recent call last):
  File "/home/airflow/.local/lib/python3.8/site-packages/airflow/models/taskinstance.py", line 433, in _execute_task
    result = execute_callable(context=context, **execute_callable_kwargs)
  File "/home/airflow/.local/lib/python3.8/site-packages/airflow/operators/python.py", line 199, in execute
    return_value = self.execute_callable()
  File "/home/airflow/.local/lib/python3.8/site-packages/airflow/operators/python.py", line 216, in execute_callable
    return self.python_callable(*self.op_args, **self.op_kwargs)
  File "/opt/airflow/dags/economic_data_daily_update.py", line 240, in update_eia_summary
    log_update('commodities', 'eia_summary', 0, 'success')
  File "/opt/airflow/dags/utils/db_helpers.py", line 42, in log_update
    hook.run(sql, parameters=(schema, table, source_id, records_added, status, error_message))
  File "/home/airflow/.local/lib/python3.8/site-packages/airflow/providers/common/sql/hooks/sql.py", line 391, in run
    with closing(self.get_conn()) as conn:
  File "/home/airflow/.local/lib/python3.8/site-packages/airflow/providers/postgres/hooks/postgres.py", line 128, in get_conn
    conn = deepcopy(self.connection or self.get_connection(conn_id))
  File "/home/airflow/.local/lib/python3.8/site-packages/airflow/hooks/base.py", line 82, in get_connection
    conn = Connection.get_connection_from_secrets(conn_id)
  File "/home/airflow/.local/lib/python3.8/site-packages/airflow/models/connection.py", line 479, in get_connection_from_secrets
    raise AirflowNotFoundException(f"The conn_id `{conn_id}` isn't defined")
airflow.exceptions.AirflowNotFoundException: The conn_id `timescaledb_conn` isn't defined
[2025-10-04T21:38:00.109+0000] {taskinstance.py:1138} INFO - Marking task as UP_FOR_RETRY. dag_id=economic_data_daily_update, task_id=update_eia_summary, execution_date=20251003T060000, start_date=20251004T213720, end_date=20251004T213800
[2025-10-04T21:38:00.147+0000] {standard_task_runner.py:107} ERROR - Failed to execute job 14 for task update_eia_summary (The conn_id `timescaledb_conn` isn't defined; 229)
[2025-10-04T21:38:00.181+0000] {local_task_job_runner.py:234} INFO - Task exited with return code 1
[2025-10-04T21:38:03.549+0000] {taskinstance.py:3280} INFO - 0 downstream tasks scheduled from follow-on schedule check
